Workbook
Name _: #REF!
Name _?__: '[1]1,2,3,4,5단위수량'!#REF!
Name ___10: #REF!
Name ___11: #REF!
Name ___6: #REF!
Name ___7: #REF!
Name ___8: #REF!
Name ___9: #REF!
Name ___A81620: [2]설계개요!#REF!
Name ___A999999: #REF!
Name ___AA158221: #REF!
Name ___BE46300: #REF!
Name ___H100000: #REF!
Name ___H600000: #REF!
Name ___H65600: #REF!
Name ___H65700: #REF!
Name ___H65900: #REF!
Name ___H66000: #REF!
Name ___H70000: #REF!
Name ___p1: #REF!
Name ___PVC100: #REF!
Name ___PVC125: #REF!
Name ___PVC150: #REF!
Name ___Q1: BlankMacro1
Name ___T57: [4]입상내역!#REF!
Name __1_3_0Crite: #REF!
Name __10: #REF!
Name __11: #REF!
Name __2_3_0Criteria: #REF!
Name __3G_0Extr: #REF!
Name __4G_0Extract: #REF!
Name __6: #REF!
Name __7: #REF!
Name __8: #REF!
Name __9: #REF!
Name __a1: [9]!BlankMacro1
Name __A100000: #REF!
Name __A183154: #REF!
Name __A66000: #REF!
Name __A67000: #REF!
Name __A68000: #REF!
Name __A80000: #REF!
Name __A81620: [2]설계개요!#REF!
Name __A999999: #REF!
Name __AA158221: #REF!
Name __AE1: BlankMacro1
Name __AE2: BlankMacro1
Name __AE3: BlankMacro1
Name __Asx3: '[10]6.교좌면보강'!#REF!
Name __Asy3: '[10]6.교좌면보강'!#REF!
Name __B140007: [11]표지!#REF!
Name __B2: '[12]단면 (2)'!$K$55
Name __BE46300: #REF!
Name __BFF1: #REF!
Name __C: #REF!
Name __C100000: #REF!
Name __DemandLoad: TRUE
Name __E1: BlankMacro1
Name __E10: BlankMacro1
Name __E2: BlankMacro1

Sheet 갑지-실행가
A1: 견 적 서
A2: ="견적내역서 일자 : "&TEXT(L2,"yyyy년 mm월 dd일") -> 견적내역서 일자 : 2026년 08월 27일 | G2: 리 더 건 설 주 식 회 사 | K2: 견적일 : | L2: =TODAY() -> 46261
A3: =L3&" 귀하" -> 귀하 | K3: 귀하 :
A4: ="공사명 : "&L4&" 중 RF-CIP "&M4 -> 공사명 : 중 RF-CIP | K4: 공사명 :
A5: 아래 와 같이 견적 합니다
G6: 서울특별시 금천구 벚꽃로 36길, 30 KS타워 927
A7: 견 적 금 액 : | B7: =H23 -> 0 | E7: =H23 -> 0 | G7: TEL)02-851-4550 FAX)02-851-4551
A8: 공 종 | B8: 규 격 | C8: 수 량 | D8: 단 위 | E8: 재 료 비 | F8: 노 무 비 | G8: 경 비 | H8: 합 계 | I8: 비 고
A9: ='내역서-실행가'!A6 -> 1. RF C.I.P | B9: ='내역서-실행가'!B6 -> Φ600, CTC 470 | C9: ='내역서-실행가'!C6 -> 1 | D9: 식 | E9: ='내역서-실행가'!F6 -> 0 | F9: ='내역서-실행가'!H6 -> 0 | G9: ='내역서-실행가'!J6 -> 0 | H9: =SUM(E9:G9) -> 0
A10: ='내역서-실행가'!A7 -> 2. 부대공 | C10: ='내역서-실행가'!C7 -> 1 | D10: 식 | E10: ='내역서-실행가'!F7 -> 0 | F10: ='내역서-실행가'!H7 -> 0 | G10: ='내역서-실행가'!J7 -> 0 | H10: =SUM(E10:G10) -> 0
A11: ='내역서-실행가'!A8 -> 3. 자재대 | C11: ='내역서-실행가'!C8 -> 1 | D11: 식 | E11: ='내역서-실행가'!F8 -> 0 | F11: ='내역서-실행가'!H8 -> 0 | G11: ='내역서-실행가'!J8 -> 0 | H11: =SUM(E11:G11) -> 0
A16: 직접 공사비 계 | E16: =SUM(E9:E15) -> 0 | F16: =SUM(F9:F15) -> 0 | G16: =SUM(G9:G15) -> 0 | H16: =SUM(H9:H15) -> 0
A17: 분진망 설치 및 해체 | C17: 1 | D17: 식
A18: 하도자 공과잡비 | C18: 5 | D18: % | H18: =(H9+H10)*C18% -> 0
A19: 간접 공사비 계 | H19: =SUM(H17:H18) -> 0
A21: 합 계 | H21: =H16+H19 -> 0
A22: 단수정리 | H22: =TRUNC(H21,-6)-H21 -> 0
A23: 견적금액 | H23: =H21+H22 -> 0
A24: ■ 견 적 조 건 | F24: ■ 수 량 산 출 조 건
A25: 1) 부가세 별도. | F25: ="1) RF-CIP TYPE(" & '[386]산출근거(RF-CIP)'!A18 & "mm) : C.T.C " & '[386]천공조서(RF-CIP)'!X6 * 1000 &" mm" -> 1) RF-CIP TYPE(Φ600mm) : C.T.C 470 mm
A26: 3) 공사용 용전, 용수, H-BEAM, 레미콘(LOSS분 포함) 지급 조건. | F26: ="2) SIDE PILE(" & '[386]산출근거(RF-CIP)'!A22 & ") : C.T.C " & '[386]천공조서(RF-CIP)'!E8 * 1000 &" mm" -> 2) SIDE PILE(H-350x350*12*19) : C.T.C 940 mm
A27: 4) 폐기물처리비, 민원처리비, 안전관련(신호수포함) 모든사항 "갑" 측 처리.
A28: 5) 천공장비 장비년식 제한 시 견적금액 변동있음.
A29: 6) 지반조사 토질조건과 현장 토질조건이 상이 할 시 설계변경 조건.
A30: 7) 소음 및 진동으로 인한 민원 발생 시 저진동 저소음 토네이도 함마 설계변경 조건.
A31: 8) 민원, 지하구조물, 지장물, 작업구간 가설휀스 간섭, 지급자재 공급지연, 기타 등으로 인한 작업대기시 대기료 정산조건.
A32: 9) 천공배출토 처리 및 H-BEAM 연결이음, 측량(시공 및 검측), 안전관리계획서 "갑"측 처리.
H33: * 상기 견적서는 50일간 유효함.

Sheet 내역서-실행가
A1: 견 적 내 역 서
A2: ='갑지-실행가'!A4 -> 공사명 : 중 RF-CIP | I2: ='갑지-실행가'!A2 -> 견적내역서 일자 : 2026년 08월 27일
A3: 공 종 | B3: 규 격 | C3: 수 량 | D3: 단위 | E3: 재 료 비 | G3: 노 무 비 | I3: 경 비 | K3: 합 계 | M3: 비 고
E4: 단 가 | F4: 금 액 | G4: 단 가 | H4: 금 액 | I4: 단 가 | J4: 금 액 | K4: 단 가 | L4: 금 액
A5: ■ 직접공사비
A6: =A12 -> 1. RF C.I.P | B6: =B12 -> Φ600, CTC 470 | C6: 1 | D6: 식 | F6: =F12 -> 0 | H6: =H12 -> 0 | J6: =J12 -> 0 | L6: =F6+H6+J6 -> 0
A7: =A18 -> 2. 부대공 | C7: 1 | D7: 식 | F7: =F18 -> 0 | H7: =H18 -> 0 | J7: =J18 -> 0 | L7: =F7+H7+J7 -> 0
A8: =A31 -> 3. 자재대 | C8: 1 | D8: 식 | F8: =F31 -> 0 | H8: =H31 -> 0 | J8: =J31 -> 0 | L8: =L31 -> 0
A10: 합 계 | F10: =SUM(F6:F9) -> 0 | H10: =SUM(H6:H9) -> 0 | J10: =SUM(J6:J9) -> 0 | L10: =SUM(L6:L9) -> 0
A12: 1. RF C.I.P | B12: =B19 & ", CTC " & RIGHT(B19,LEN(B19)-1)-130 -> Φ600, CTC 470 | F12: =SUM(F13:F14) -> 0 | H12: =SUM(H13:H14) -> 0 | J12: =SUM(J13:J14) -> 0 | L12: =SUM(L13:L14) -> 0
A13: RF C.I.P 천공 | B13: 토사 | C13: ='산출근거(RF-CIP)'!AD6+'산출근거(RF-CIP)'!AD7 -> 1620 | D13: M | E13: =TRUNC(K13*0.3) -> 0 | F13: =TRUNC(L13*0.3) -> 0 | G13: =TRUNC(M13*0.3) -> 0 | H13: =TRUNC(N13*0.3) -> 0 | I13: =TRUNC(O13*0.3) -> 0 | J13: =TRUNC(P13*0.3) -> 0 | K13: =TRUNC(Q13*0.3) -> 0 | L13: =TRUNC(R13*0.3) -> 0
A14: RF C.I.P 천공 | B14: ='[386]산출근거(RF-CIP)'!A8 -> 풍화암 | C14: ='산출근거(RF-CIP)'!AD9 -> 324 | D14: M | E14: =TRUNC(K14*0.3) -> 0 | F14: =TRUNC(L14*0.3) -> 0 | G14: =TRUNC(M14*0.3) -> 0 | H14: =TRUNC(N14*0.3) -> 0 | I14: =TRUNC(O14*0.3) -> 0 | J14: =TRUNC(P14*0.3) -> 0 | K14: =TRUNC(Q14*0.3) -> 0 | L14: =TRUNC(R14*0.3) -> 0
A15: RF C.I.P 천공 | B15: ='[386]산출근거(RF-CIP)'!A10 -> 연암 | C15: ='산출근거(RF-CIP)'!AD11 -> 108 | D15: M | E15: =TRUNC(K15*0.3) -> 0 | F15: =TRUNC(L15*0.3) -> 0 | G15: =TRUNC(M15*0.3) -> 0 | H15: =TRUNC(N15*0.3) -> 0 | I15: =TRUNC(O15*0.3) -> 0 | J15: =TRUNC(P15*0.3) -> 0 | K15: =TRUNC(Q15*0.3) -> 0 | L15: =TRUNC(R15*0.3) -> 0
A16: RF C.I.P 천공 | B16: ='[386]산출근거(RF-CIP)'!A14 -> 경암 | C16: ='산출근거(RF-CIP)'!AD13 -> 0 | D16: M | E16: =TRUNC(K16*0.3) -> 0 | F16: =TRUNC(L16*0.3) -> 0 | G16: =TRUNC(M16*0.3) -> 0 | H16: =TRUNC(N16*0.3) -> 0 | I16: =TRUNC(O16*0.3) -> 0 | J16: =TRUNC(P16*0.3) -> 0 | K16: =TRUNC(Q16*0.3) -> 0 | L16: =TRUNC(R16*0.3) -> 0
A18: 2. 부대공 | F18: =SUM(F19:F29) -> 0 | H18: =SUM(H19:H29) -> 0 | J18: =SUM(J19:J29) -> 0 | L18: =SUM(L19:L29) -> 0
A19: 케이싱 설치 및 철거 | B19: ='[386]산출근거(RF-CIP)'!A18 -> Φ600 | C19: ='산출근거(RF-CIP)'!AD15 -> 1944 | D19: M | E19: =TRUNC(K19*0.3) -> 0 | F19: =TRUNC(E19*C19,0) -> 0 | G19: =TRUNC(K19*0.2) -> 0 | H19: =TRUNC(G19*C19,0) -> 0 | I19: =TRUNC(K19*0.5) -> 0 | J19: =TRUNC(I19*C19,0) -> 0 | L19: =F19+H19+J19 -> 0
A20: H-PILE 근입 | B20: ='[386]산출근거(RF-CIP)'!A22 -> H-350x350*12*19 | C20: ='산출근거(RF-CIP)'!AD18 -> 1080 | D20: M | E20: =TRUNC(K20*0.3) -> 0 | F20: =TRUNC(E20*C20,0) -> 0 | G20: =TRUNC(K20*0.2) -> 0 | H20: =TRUNC(G20*C20,0) -> 0 | I20: =TRUNC(K20*0.5) -> 0 | J20: =TRUNC(I20*C20,0) -> 0 | L20: =F20+H20+J20 -> 0
A21: H-PILE 연결 | B21: ='[386]산출근거(RF-CIP)'!A28 -> H-350x350*12*19 | C21: ='산출근거(RF-CIP)'!AD26 -> 54 | D21: 개소 | E21: =TRUNC(K21*0.3) -> 0 | F21: =TRUNC(E21*C21,0) -> 0 | G21: =TRUNC(K21*0.2) -> 0 | H21: =TRUNC(G21*C21,0) -> 0 | I21: =TRUNC(K21*0.5) -> 0 | J21: =TRUNC(I21*C21,0) -> 0 | L21: =F21+H21+J21 -> 0
A22: 레미콘 타설 | B22: ='[386]산출근거(RF-CIP)'!A35 -> fck=18MPa | C22: ='산출근거(RF-CIP)'!AD34 -> 579.9 | D22: M3 | E22: =TRUNC(K22*0.3) -> 0 | F22: =TRUNC(E22*C22,0) -> 0 | G22: =TRUNC(K22*0.2) -> 0 | H22: =TRUNC(G22*C22,0) -> 0 | I22: =TRUNC(K22*0.5) -> 0 | J22: =TRUNC(I22*C22,0) -> 0 | L22: =F22+H22+J22 -> 0
A23: 천공배출토 정리 | B23: 정리 및 상차비 | C23: ='산출근거(RF-CIP)'!AD38 -> 579.9 | D23: M3 | E23: =TRUNC(K23*0.3) -> 0 | F23: =TRUNC(E23*C23,0) -> 0 | G23: =TRUNC(K23*0.2) -> 0 | H23: =TRUNC(G23*C23,0) -> 0 | I23: =TRUNC(K23*0.5) -> 0 | J23: =TRUNC(I23*C23,0) -> 0 | L23: =F23+H23+J23 -> 0
A24: 가이드월 터파기 및 되메우기 | B24: 1.5m x 1.0m | C24: ='산출근거(RF-CIP)'!AD43 -> 50 | D24: M | E24: =TRUNC(K24*0.3) -> 0 | F24: =TRUNC(E24*C24,0) -> 0 | G24: =TRUNC(K24*0.2) -> 0 | H24: =TRUNC(G24*C24,0) -> 0 | I24: =TRUNC(K24*0.5) -> 0 | J24: =TRUNC(I24*C24,0) -> 0 | L24: =F24+H24+J24 -> 0
A25: 가이드월 손료 | B25: ='[386]산출근거(RF-CIP)'!A48 -> H=1.0m , Φ600 | C25: ='산출근거(RF-CIP)'!AD45 -> 50 | D25: M | F25: =TRUNC(E25*C25,0) -> 0 | H25: =TRUNC(G25*C25,0) -> 0 | I25: =K25 -> 0 | J25: =TRUNC(I25*C25,0) -> 0 | L25: =F25+H25+J25 -> 0
A26: 가이드월 설치 및 해체 | B26: =B25 -> H=1.0m , Φ600 | C26: ='산출근거(RF-CIP)'!AD45 -> 50 | D26: M | E26: =TRUNC(K26*0.3) -> 0 | F26: =TRUNC(E26*C26,0) -> 0 | G26: =TRUNC(K26*0.2) -> 0 | H26: =TRUNC(G26*C26,0) -> 0 | I26: =TRUNC(K26*0.5) -> 0 | J26: =TRUNC(I26*C26,0) -> 0 | L26: =F26+H26+J26 -> 0
A27: 강재소운반(H빔) | B27: 역내 20KM | C27: ='산출근거(RF-CIP)'!AD22 -> 108.6264 | D27: TON | F27: =TRUNC(E27*C27,0) -> 0 | H27: =TRUNC(G27*C27,0) -> 0 | I27: =K27 -> 0 | J27: =TRUNC(I27*C27,0) -> 0 | L27: =F27+H27+J27 -> 0
A28: 가이드월 운반 | B28: 왕복 100KM | C28: ='산출근거(RF-CIP)'!AD47 -> 1 | D28: 회 | F28: =TRUNC(E28*C28,0) -> 0 | H28: =TRUNC(G28*C28,0) -> 0 | I28: =K28 -> 0 | J28: =TRUNC(I28*C28,0) -> 0 | L28: =F28+H28+J28 -> 0
A29: 항타항발기 운반 및 조립해체 | B29: 왕복 | C29: ='산출근거(RF-CIP)'!AD49 -> 1 | D29: 회 | F29: =TRUNC(E29*C29,0) -> 0 | H29: =TRUNC(G29*C29,0) -> 0 | I29: =K29 -> 0 | J29: =TRUNC(I29*C29,0) -> 0 | L29: =F29+H29+J29 -> 0
A31: 3. 자재대 | F31: =SUM(F32:F33) -> 0 | H31: =SUM(H32:H33) -> 0 | J31: =SUM(J32:J33) -> 0 | L31: =SUM(L32:L33) -> 0
A32: ='[386]산출근거(RF-CIP)'!A28 -> H-350x350*12*19 | B32: 사장 | C32: ='산출근거(RF-CIP)'!AD22 -> 108.6264 | D32: Ton | E32: =K32 -> 0 | F32: =TRUNC(E32*C32,0) -> 0 | G32: =[386]단가집계표!I23 -> 0 | H32: =TRUNC(G32*C32,0) -> 0 | I32: =[386]단가집계표!K23 -> 0 | J32: =TRUNC(I32*C32,0) -> 0 | L32: =F32+H32+J32 -> 0 | M32: 원도급사분
A33: 레미콘 | B33: =B22 -> fck=18MPa | C33: ='산출근거(RF-CIP)'!AD36 -> 591.498 | D33: M3 | E33: =K33 -> 0 | F33: =TRUNC(E33*C33,0) -> 0 | G33: =[386]단가집계표!I24 -> 0 | H33: =TRUNC(G33*C33,0) -> 0 | I33: =[386]단가집계표!K24 -> 0 | J33: =TRUNC(I33*C33,0) -> 0 | L33: =F33+H33+J33 -> 0 | M33: 관급자재

Sheet 산출근거(RF-CIP)
A1: 3. RF-CIP 산출근거
A2: 공 종 | B2: 산 출 근 거 | AD2: 수 량
A3: ○ RF-C.I.P 수량산출
A4: 1. 천공
A5: ='천공조서(RF-CIP)'!B4 -> 토사 | B5: - | C5: ='천공조서(RF-CIP)'!O61+'천공조서(RF-CIP)'!C61 -> 1620 | F5: m
A6: 1차 천공 (무근) | C6: =C5 -> 1620 | F6: / | G6: 2 | AC6: = | AD6: =C6/G6 -> 810 | AE6: M
A7: 2차 천공 (절삭공) | C7: =C5 -> 1620 | F7: / | G7: 2 | AC7: = | AD7: =C7/G7 -> 810 | AE7: M
A8: ='천공조서(RF-CIP)'!D4 -> 풍화암 | B8: - | C8: ='천공조서(RF-CIP)'!E61+'천공조서(RF-CIP)'!Q61 -> 324 | F8: m
A9: 천공 | C9: =C8 -> 324 | AC9: = | AD9: =C9 -> 324 | AE9: M
A10: ='천공조서(RF-CIP)'!F4 -> 연암 | B10: - | C10: ='천공조서(RF-CIP)'!G61+'천공조서(RF-CIP)'!S61 -> 108 | F10: m
A11: 천공 | C11: =C10 -> 108 | AC11: = | AD11: =C11 -> 108 | AE11: M
A12: ='천공조서(RF-CIP)'!H4 -> 경암 | B12: - | C12: ='천공조서(RF-CIP)'!I61+'천공조서(RF-CIP)'!U61 -> 0 | F12: m
A13: 천공 | C13: =C12 -> 0 | AC13: = | AD13: =C13 -> 0 | AE13: M
A15: 2. 케이싱튜브 설치 및 철거 | B15: - | C15: =C5 -> 1620 | F15: + | G15: =C8 -> 324 | AC15: = | AD15: =ROUND(C15+G15+K15+O15,2) -> 1944 | AE15: M
G16: 풍화암까지
A17: 3. H-Pile 근입
A18: 1) H-Pile 근입 | B18: - | C18: ='천공조서(RF-CIP)'!J61 -> 1080 | F18: M | AC18: = | AD18: =ROUND(C18,2) -> 1080 | AE18: M
A19: 2) H-Pile 중량 | B19: - | C19: L = | E19: =C18 -> 1080 | H19: m
A20: H-300x300*10*15 | B20: - | C20: =E19 -> 1080 | G20: x | H20: 94 | J20: kg/m / 1000 | AC20: = | AD20: =ROUND(C20*H20/1000,3) -> 101.52 | AE20: ton
A21: 할증 | C21: =AD20 -> 101.52 | G21: x | H21: 7 | J21: % | AC21: = | AD21: =C21*H21% -> 7.1064 | AE21: M3
AC22: = | AD22: =AD20+AD21 -> 108.6264 | AE22: M3
A24: 4-1. H-Pile 연결 | AD24: =C24 -> 0
A25: (가시설분)
A26: =A20 -> H-300x300*10*15 | B26: - | C26: ='천공조서(RF-CIP)'!K61 -> 54 | E26: 개소 | AC26: = | AD26: =C26 -> 54 | AE26: 개소
A28: 4-2. H-Pile 연결판
A29: ="PL-" & L29*1000 & "x" & O29*1000 & "x" & R29*1000 -> PL-600x200x14 | B29: - | C29: =AD26 -> 54 | E29: 개소 | G29: x | H29: 2 | J29: ea | K29: x | L29: 0.6 | N29: x | O29: 0.2 | Q29: x | R29: 0.014 | T29: x | U29: 7.85 | W29: t/m3 | AC29: = | AD29: =ROUND(C29*H29*L29*O29*R29*U29,3) -> 1.424 | AE29: ton
A30: ="PL-" & L30*1000 & "x" & O30*1000 & "x" & R30*1000 -> PL-600x280x14 | B30: - | C30: =AD26 -> 54 | E30: 개소 | G30: x | H30: 2 | J30: ea | K30: x | L30: 0.6 | N30: x | O30: 0.28 | Q30: x | R30: 0.014 | T30: x | U30: 7.85 | W30: t/m3 | AC30: = | AD30: =ROUND(C30*H30*L30*O30*R30*U30,3) -> 1.994 | AE30: ton
A32: 5. 콘크리트 타설 | B32: - | C32: =C5 -> 1620 | F32: + | G32: =C8 -> 324 | J32: + | K32: =C10 -> 108 | N32: + | O32: =C12 -> 0 | V32: = | W32: =ROUND(C32+G32+K32+O32,2) -> 2052 | AA32: m
A33: fck=18MPa | B33: - | C33: 콘크리트 타설량
C34: ( | D34: 3.14 | F34: x | G34: ='천공조서(RF-CIP)'!Z3 -> 0.6 | I34: ^ | J34: 2 | L34: ) | M34: / | N34: 4 | P34: x | Q34: =W32 -> 2052 | U34: m | AC34: = | AD34: =ROUND(3.14*G34^2/4*Q34,2) -> 579.9 | AE34: M3
A35: 할증 | C35: =AD34 -> 579.9 | F35: x | G35: 2 | I35: % | AC35: = | AD35: =C35*G35% -> 11.598 | AE35: M3
AC36: = | AD36: =AD34+AD35 -> 591.498 | AE36: M3
A38: 6. 천공배출토 정리및상차 | B38: - | C38: ( | D38: 3.14 | F38: x | G38: =G34 -> 0.6 | I38: ^ | J38: 2 | L38: ) | M38: / | N38: 4 | P38: x | Q38: =Q34 -> 2052 | U38: m | AC38: = | AD38: =ROUND(3.14*G38^2/4*Q38,2) -> 579.9 | AE38: M3
A40: 7. 천공배출토 잔토처리 | B40: - | C40: ( | D40: 3.14 | F40: x | G40: =G38 -> 0.6 | I40: ^ | J40: 2 | L40: ) | M40: / | N40: 4 | P40: x | Q40: =Q38 -> 2052 | U40: m | V40: x | W40: 120 | Z40: % | AC40: = | AD40: =ROUND(3.14*G40^2/4*Q40*W40%,2) -> 695.87 | AE40: M3
A41: (토공사분)
A43: 8. 가이드월 터파기 및 되메우기 | B43: - | C43: ='천공조서(RF-CIP)'!Z5 -> 50 | AC43: = | AD43: =ROUND(C43,2) -> 50 | AE43: M
A44: 1.5m x 1.0m
A45: 9. 가이드월 설치및해체 | B45: - | C45: =C43 -> 50 | AC45: = | AD45: =ROUND(C45,2) -> 50 | AE45: M
A46: ="H=1.0m , " & A16 -> H=1.0m ,
A47: 10. 가이드월 운반 | B47: - | C47: 1 | F47: 회 | AC47: = | AD47: =ROUND(C47,2) -> 1 | AE47: 회
...

Sheet 천공조서(RF-CIP)
Y1: 설계 파라미터
Y2: 구분 | Z2: 값 | AA2: 단위 | AB2: 비고
A3: PILE NO. | B3: H-PILE 구간 천공 (M) | K3: H-PILE 연결 | M3: PILE NO. | N3: 무 근 천 공 (M) | Y3: 직경 | Z3: 0.6 | AA3: m | AB3: 설계값
B4: 토사 | D4: 풍화암 | F4: 연암 | H4: 경암 | N4: =B4 -> 토사 | P4: =D4 -> 풍화암 | R4: =F4 -> 연암 | T4: =H4 -> 경암 | Y4: C.T.C | Z4: 0.47 | AA4: m | AB4: 중심간거리
A5: H-PILE | B5: 공당 | C5: 소계 | D5: 공당 | E5: 소계 | F5: 공당 | G5: 소계 | H5: 공당 | I5: 소계 | J5: 합계 | M5: 무 근 | N5: 공당 | O5: 소계 | P5: 공당 | Q5: 소계 | R5: 공당 | S5: 소계 | T5: 공당 | U5: 소계 | V5: 합계 | X5: 구간 | Y5: 가시설 연장 | Z5: 50 | AA5: m | AB5: 벽면 연장
A6: 1 | B6: 15 | C6: =B6 -> 15 | D6: 3 | E6: =D6 -> 3 | F6: 2 | G6: =F6 -> 2 | H6: 0 | I6: =H6 -> 0 | J6: =B6+D6+F6+H6 -> 20 | K6: 1 | M6: 1-1 | N6: =B6 -> 15 | O6: =N6 -> 15 | P6: =D6 -> 3 | Q6: =P6 -> 3 | R6: 0 | S6: =R6 -> 0 | T6: =H6 -> 0 | U6: =T6 -> 0 | V6: =N6+P6+R6+T6 -> 18 | Y6: 측면말뚝 간격 | Z6: 0.94 | AA6: m
A7: 2 | B7: 15 | C7: =B7 -> 15 | D7: 3 | E7: =D7 -> 3 | F7: 2 | G7: =F7 -> 2 | H7: 0 | I7: =H7 -> 0 | J7: =B7+D7+F7+H7 -> 20 | K7: 1 | M7: 2-1 | N7: =B7 -> 15 | O7: =N7 -> 15 | P7: =D7 -> 3 | Q7: =P7 -> 3 | R7: 0 | S7: =R7 -> 0 | T7: =H7 -> 0 | U7: =T7 -> 0 | V7: =N7+P7+R7+T7 -> 18 | Y7: 총 공수 | Z7: =Z9+Z8 -> 108 | AA7: 공 | AB7: 연장÷C.T.C
A8: 3 | B8: 15 | C8: =B8 -> 15 | D8: 3 | E8: =D8 -> 3 | F8: 2 | G8: =F8 -> 2 | H8: 0 | I8: =H8 -> 0 | J8: =B8+D8+F8+H8 -> 20 | K8: 1 | M8: 3-1 | N8: =B8 -> 15 | O8: =N8 -> 15 | P8: =D8 -> 3 | Q8: =P8 -> 3 | R8: 0 | S8: =R8 -> 0 | T8: =H8 -> 0 | U8: =T8 -> 0 | V8: =N8+P8+R8+T8 -> 18 | Y8: H-PILE 본수 | Z8: 54 | AA8: 본 | AB8: 총공수÷2
A9: 4 | B9: 15 | C9: =B9 -> 15 | D9: 3 | E9: =D9 -> 3 | F9: 2 | G9: =F9 -> 2 | H9: 0 | I9: =H9 -> 0 | J9: =B9+D9+F9+H9 -> 20 | K9: 1 | M9: 4-1 | N9: =B9 -> 15 | O9: =N9 -> 15 | P9: =D9 -> 3 | Q9: =P9 -> 3 | R9: 0 | S9: =R9 -> 0 | T9: =H9 -> 0 | U9: =T9 -> 0 | V9: =N9+P9+R9+T9 -> 18 | Y9: 무근 본수 | Z9: 54 | AA9: 본 | AB9: 총공수−H-PILE
A10: 5 | B10: 15 | C10: =B10 -> 15 | D10: 3 | E10: =D10 -> 3 | F10: 2 | G10: =F10 -> 2 | H10: 0 | I10: =H10 -> 0 | J10: =B10+D10+F10+H10 -> 20 | K10: 1 | M10: 5-1 | N10: =B10 -> 15 | O10: =N10 -> 15 | P10: =D10 -> 3 | Q10: =P10 -> 3 | R10: 0 | S10: =R10 -> 0 | T10: =H10 -> 0 | U10: =T10 -> 0 | V10: =N10+P10+R10+T10 -> 18
A11: 6 | B11: 15 | C11: =B11 -> 15 | D11: 3 | E11: =D11 -> 3 | F11: 2 | G11: =F11 -> 2 | H11: 0 | I11: =H11 -> 0 | J11: =B11+D11+F11+H11 -> 20 | K11: 1 | M11: 6-1 | N11: =B11 -> 15 | O11: =N11 -> 15 | P11: =D11 -> 3 | Q11: =P11 -> 3 | R11: 0 | S11: =R11 -> 0 | T11: =H11 -> 0 | U11: =T11 -> 0 | V11: =N11+P11+R11+T11 -> 18
A12: 7 | B12: 15 | C12: =B12 -> 15 | D12: 3 | E12: =D12 -> 3 | F12: 2 | G12: =F12 -> 2 | H12: 0 | I12: =H12 -> 0 | J12: =B12+D12+F12+H12 -> 20 | K12: 1 | M12: 7-1 | N12: =B12 -> 15 | O12: =N12 -> 15 | P12: =D12 -> 3 | Q12: =P12 -> 3 | R12: 0 | S12: =R12 -> 0 | T12: =H12 -> 0 | U12: =T12 -> 0 | V12: =N12+P12+R12+T12 -> 18 | Y12: 지반 조건별 평균 천공 깊이
A13: 8 | B13: 15 | C13: =B13 -> 15 | D13: 3 | E13: =D13 -> 3 | F13: 2 | G13: =F13 -> 2 | H13: 0 | I13: =H13 -> 0 | J13: =B13+D13+F13+H13 -> 20 | K13: 1 | M13: 8-1 | N13: =B13 -> 15 | O13: =N13 -> 15 | P13: =D13 -> 3 | Q13: =P13 -> 3 | R13: 0 | S13: =R13 -> 0 | T13: =H13 -> 0 | U13: =T13 -> 0 | V13: =N13+P13+R13+T13 -> 18 | Y13: 지반조건 | Z13: 평균 깊이(m) | AA13: 해당 공수 | AB13: 총 연장(m)
A14: 9 | B14: 15 | C14: =B14 -> 15 | D14: 3 | E14: =D14 -> 3 | F14: 2 | G14: =F14 -> 2 | H14: 0 | I14: =H14 -> 0 | J14: =B14+D14+F14+H14 -> 20 | K14: 1 | M14: 9-1 | N14: =B14 -> 15 | O14: =N14 -> 15 | P14: =D14 -> 3 | Q14: =P14 -> 3 | R14: 0 | S14: =R14 -> 0 | T14: =H14 -> 0 | U14: =T14 -> 0 | V14: =N14+P14+R14+T14 -> 18 | Y14: 토사 | Z14: =IFERROR(AVERAGEIF(B6:B60,">0"),0) -> 15 | AA14: =COUNTIF(B6:B60,">0") -> 54 | AB14: =SUM(B6:B60) -> 810
A15: 10 | B15: 15 | C15: =B15 -> 15 | D15: 3 | E15: =D15 -> 3 | F15: 2 | G15: =F15 -> 2 | H15: 0 | I15: =H15 -> 0 | J15: =B15+D15+F15+H15 -> 20 | K15: 1 | M15: 10-1 | N15: =B15 -> 15 | O15: =N15 -> 15 | P15: =D15 -> 3 | Q15: =P15 -> 3 | R15: 0 | S15: =R15 -> 0 | T15: =H15 -> 0 | U15: =T15 -> 0 | V15: =N15+P15+R15+T15 -> 18 | Y15: 풍화암 | Z15: =IFERROR(AVERAGEIF(D6:D60,">0"),0) -> 3 | AA15: =COUNTIF(D6:D60,">0") -> 54 | AB15: =SUM(D6:D60) -> 162
A16: 11 | B16: 15 | C16: =B16 -> 15 | D16: 3 | E16: =D16 -> 3 | F16: 2 | G16: =F16 -> 2 | H16: 0 | I16: =H16 -> 0 | J16: =B16+D16+F16+H16 -> 20 | K16: 1 | M16: 11-1 | N16: =B16 -> 15 | O16: =N16 -> 15 | P16: =D16 -> 3 | Q16: =P16 -> 3 | R16: 0 | S16: =R16 -> 0 | T16: =H16 -> 0 | U16: =T16 -> 0 | V16: =N16+P16+R16+T16 -> 18 | Y16: 연암 | Z16: =IFERROR(AVERAGEIF(F6:F60,">0"),0) -> 2 | AA16: =COUNTIF(F6:F60,">0") -> 54 | AB16: =SUM(F6:F60) -> 108
A17: 12 | B17: 15 | C17: =B17 -> 15 | D17: 3 | E17: =D17 -> 3 | F17: 2 | G17: =F17 -> 2 | H17: 0 | I17: =H17 -> 0 | J17: =B17+D17+F17+H17 -> 20 | K17: 1 | M17: 12-1 | N17: =B17 -> 15 | O17: =N17 -> 15 | P17: =D17 -> 3 | Q17: =P17 -> 3 | R17: 0 | S17: =R17 -> 0 | T17: =H17 -> 0 | U17: =T17 -> 0 | V17: =N17+P17+R17+T17 -> 18 | Y17: 경암 | Z17: =IFERROR(AVERAGEIF(H6:H60,">0"),0) -> 0 | AA17: =COUNTIF(H6:H60,">0") -> 0 | AB17: =SUM(H6:H60) -> 0
A18: 13 | B18: 15 | C18: =B18 -> 15 | D18: 3 | E18: =D18 -> 3 | F18: 2 | G18: =F18 -> 2 | H18: 0 | I18: =H18 -> 0 | J18: =B18+D18+F18+H18 -> 20 | K18: 1 | M18: 13-1 | N18: =B18 -> 15 | O18: =N18 -> 15 | P18: =D18 -> 3 | Q18: =P18 -> 3 | R18: 0 | S18: =R18 -> 0 | T18: =H18 -> 0 | U18: =T18 -> 0 | V18: =N18+P18+R18+T18 -> 18 | Y18: 전체(공당 평균) | Z18: =IFERROR(AB18/AA18,0) -> 20 | AA18: =COUNT(A6:A60) -> 54 | AB18: =SUM(AB14:AB17) -> 1080
A19: 14 | B19: 15 | C19: =B19 -> 15 | D19: 3 | E19: =D19 -> 3 | F19: 2 | G19: =F19 -> 2 | H19: 0 | I19: =H19 -> 0 | J19: =B19+D19+F19+H19 -> 20 | K19: 1 | M19: 14-1 | N19: =B19 -> 15 | O19: =N19 -> 15 | P19: =D19 -> 3 | Q19: =P19 -> 3 | R19: 0 | S19: =R19 -> 0 | T19: =H19 -> 0 | U19: =T19 -> 0 | V19: =N19+P19+R19+T19 -> 18
A20: 15 | B20: 15 | C20: =B20 -> 15 | D20: 3 | E20: =D20 -> 3 | F20: 2 | G20: =F20 -> 2 | H20: 0 | I20: =H20 -> 0 | J20: =B20+D20+F20+H20 -> 20 | K20: 1 | M20: 15-1 | N20: =B20 -> 15 | O20: =N20 -> 15 | P20: =D20 -> 3 | Q20: =P20 -> 3 | R20: 0 | S20: =R20 -> 0 | T20: =H20 -> 0 | U20: =T20 -> 0 | V20: =N20+P20+R20+T20 -> 18
A21: 16 | B21: 15 | C21: =B21 -> 15 | D21: 3 | E21: =D21 -> 3 | F21: 2 | G21: =F21 -> 2 | H21: 0 | I21: =H21 -> 0 | J21: =B21+D21+F21+H21 -> 20 | K21: 1 | M21: 16-1 | N21: =B21 -> 15 | O21: =N21 -> 15 | P21: =D21 -> 3 | Q21: =P21 -> 3 | R21: 0 | S21: =R21 -> 0 | T21: =H21 -> 0 | U21: =T21 -> 0 | V21: =N21+P21+R21+T21 -> 18
A22: 17 | B22: 15 | C22: =B22 -> 15 | D22: 3 | E22: =D22 -> 3 | F22: 2 | G22: =F22 -> 2 | H22: 0 | I22: =H22 -> 0 | J22: =B22+D22+F22+H22 -> 20 | K22: 1 | M22: 17-1 | N22: =B22 -> 15 | O22: =N22 -> 15 | P22: =D22 -> 3 | Q22: =P22 -> 3 | R22: 0 | S22: =R22 -> 0 | T22: =H22 -> 0 | U22: =T22 -> 0 | V22: =N22+P22+R22+T22 -> 18
A23: 18 | B23: 15 | C23: =B23 -> 15 | D23: 3 | E23: =D23 -> 3 | F23: 2 | G23: =F23 -> 2 | H23: 0 | I23: =H23 -> 0 | J23: =B23+D23+F23+H23 -> 20 | K23: 1 | M23: 18-1 | N23: =B23 -> 15 | O23: =N23 -> 15 | P23: =D23 -> 3 | Q23: =P23 -> 3 | R23: 0 | S23: =R23 -> 0 | T23: =H23 -> 0 | U23: =T23 -> 0 | V23: =N23+P23+R23+T23 -> 18
A24: 19 | B24: 15 | C24: =B24 -> 15 | D24: 3 | E24: =D24 -> 3 | F24: 2 | G24: =F24 -> 2 | H24: 0 | I24: =H24 -> 0 | J24: =B24+D24+F24+H24 -> 20 | K24: 1 | M24: 19-1 | N24: =B24 -> 15 | O24: =N24 -> 15 | P24: =D24 -> 3 | Q24: =P24 -> 3 | R24: 0 | S24: =R24 -> 0 | T24: =H24 -> 0 | U24: =T24 -> 0 | V24: =N24+P24+R24+T24 -> 18
A25: 20 | B25: 15 | C25: =B25 -> 15 | D25: 3 | E25: =D25 -> 3 | F25: 2 | G25: =F25 -> 2 | H25: 0 | I25: =H25 -> 0 | J25: =B25+D25+F25+H25 -> 20 | K25: 1 | M25: 20-1 | N25: =B25 -> 15 | O25: =N25 -> 15 | P25: =D25 -> 3 | Q25: =P25 -> 3 | R25: 0 | S25: =R25 -> 0 | T25: =H25 -> 0 | U25: =T25 -> 0 | V25: =N25+P25+R25+T25 -> 18
A26: 21 | B26: 15 | C26: =B26 -> 15 | D26: 3 | E26: =D26 -> 3 | F26: 2 | G26: =F26 -> 2 | H26: 0 | I26: =H26 -> 0 | J26: =B26+D26+F26+H26 -> 20 | K26: 1 | M26: 21-1 | N26: =B26 -> 15 | O26: =N26 -> 15 | P26: =D26 -> 3 | Q26: =P26 -> 3 | R26: 0 | S26: =R26 -> 0 | T26: =H26 -> 0 | U26: =T26 -> 0 | V26: =N26+P26+R26+T26 -> 18
A27: 22 | B27: 15 | C27: =B27 -> 15 | D27: 3 | E27: =D27 -> 3 | F27: 2 | G27: =F27 -> 2 | H27: 0 | I27: =H27 -> 0 | J27: =B27+D27+F27+H27 -> 20 | K27: 1 | M27: 22-1 | N27: =B27 -> 15 | O27: =N27 -> 15 | P27: =D27 -> 3 | Q27: =P27 -> 3 | R27: 0 | S27: =R27 -> 0 | T27: =H27 -> 0 | U27: =T27 -> 0 | V27: =N27+P27+R27+T27 -> 18
A28: 23 | B28: 15 | C28: =B28 -> 15 | D28: 3 | E28: =D28 -> 3 | F28: 2 | G28: =F28 -> 2 | H28: 0 | I28: =H28 -> 0 | J28: =B28+D28+F28+H28 -> 20 | K28: 1 | M28: 23-1 | N28: =B28 -> 15 | O28: =N28 -> 15 | P28: =D28 -> 3 | Q28: =P28 -> 3 | R28: 0 | S28: =R28 -> 0 | T28: =H28 -> 0 | U28: =T28 -> 0 | V28: =N28+P28+R28+T28 -> 18
A29: 24 | B29: 15 | C29: =B29 -> 15 | D29: 3 | E29: =D29 -> 3 | F29: 2 | G29: =F29 -> 2 | H29: 0 | I29: =H29 -> 0 | J29: =B29+D29+F29+H29 -> 20 | K29: 1 | M29: 24-1 | N29: =B29 -> 15 | O29: =N29 -> 15 | P29: =D29 -> 3 | Q29: =P29 -> 3 | R29: 0 | S29: =R29 -> 0 | T29: =H29 -> 0 | U29: =T29 -> 0 | V29: =N29+P29+R29+T29 -> 18
A30: 25 | B30: 15 | C30: =B30 -> 15 | D30: 3 | E30: =D30 -> 3 | F30: 2 | G30: =F30 -> 2 | H30: 0 | I30: =H30 -> 0 | J30: =B30+D30+F30+H30 -> 20 | K30: 1 | M30: 25-1 | N30: =B30 -> 15 | O30: =N30 -> 15 | P30: =D30 -> 3 | Q30: =P30 -> 3 | R30: 0 | S30: =R30 -> 0 | T30: =H30 -> 0 | U30: =T30 -> 0 | V30: =N30+P30+R30+T30 -> 18
... A59: 54 | B59: 15 | C59: =B59 -> 15 | D59: 3 | E59: =D59 -> 3 | F59: 2 | G59: =F59 -> 2 | H59: 0 | I59: =H59 -> 0 | J59: =B59+D59+F59+H59 -> 20 | K59: 1 | M59: 54-1 | N59: =B59 -> 15 | O59: =N59 -> 15 | P59: =D59 -> 3 | Q59: =P59 -> 3 | R59: 0 | S59: =R59 -> 0 | T59: =H59 -> 0 | U59: =T59 -> 0 | V59: =N59+P59+R59+T59 -> 18
A61: =COUNT(A6:A34) -> 29 | C61: =SUM(C6:C60) -> 810 | E61: =SUM(E6:E60) -> 162 | G61: =SUM(G6:G60) -> 108 | I61: =SUM(I6:I60) -> 0 | J61: =SUM(J6:J60) -> 1080 | K61: =SUM(K6:K60) -> 54 | O61: =SUM(O6:O60) -> 810 | Q61: =SUM(Q6:Q60) -> 162 | S61: =SUM(S6:S60) -> 0 | U61: =SUM(U6:U60) -> 0 | V61: =SUM(V6:V59) -> 972
